{
  "cells": [
    {
      "cell_type": "code",
      "execution_count": 2,
      "metadata": {
        "colab": {
          "base_uri": "https://localhost:8080/"
        },
        "id": "EUyHAYzGHKxp",
        "outputId": "3b0d97b1-26d0-4ecc-9123-ea4adf90c5b4"
      },
      "outputs": [
        {
          "name": "stdout",
          "output_type": "stream",
          "text": [
            "<module 'requests' from '/usr/local/lib/python3.11/dist-packages/requests/__init__.py'>\n"
          ]
        }
      ],
      "source": [
        "import requests\n",
        "print(requests)"
      ]
    },
    {
      "cell_type": "code",
      "execution_count": null,
      "metadata": {
        "id": "g123hvt7HzJg"
      },
      "outputs": [],
      "source": [
        "ApiNewsKey="
      ]
    },
    {
      "cell_type": "code",
      "execution_count": 59,
      "metadata": {
        "id": "ygjzyQ_MH_Va"
      },
      "outputs": [],
      "source": [
        "async def get_news():\n",
        "    keyword = input(\"검색어를 입력하세요 : \")\n",
        "    url = f\"https://newsapi.org/v2/everything?q={keyword}&language=ko&apiKey={ApiNewsKey}\"\n",
        "    response = requests.get(url).json()\n",
        "    for i in response['articles']:\n",
        "        print(i['title'],i['description'])\n"
      ]
    },
    {
      "cell_type": "code",
      "execution_count": 49,
      "metadata": {
        "colab": {
          "base_uri": "https://localhost:8080/"
        },
        "id": "C-g2egsvLnLM",
        "outputId": "6e4a1548-118b-4e73-ae55-641aa95c71b5"
      },
      "outputs": [
        {
          "name": "stdout",
          "output_type": "stream",
          "text": [
            "Collecting python-telegram-bot\n",
            "  Downloading python_telegram_bot-22.1-py3-none-any.whl.metadata (17 kB)\n",
            "Requirement already satisfied: httpx~=0.27 in /usr/local/lib/python3.11/dist-packages (from python-telegram-bot) (0.28.1)\n",
            "Requirement already satisfied: anyio in /usr/local/lib/python3.11/dist-packages (from httpx~=0.27->python-telegram-bot) (4.9.0)\n",
            "Requirement already satisfied: certifi in /usr/local/lib/python3.11/dist-packages (from httpx~=0.27->python-telegram-bot) (2025.4.26)\n",
            "Requirement already satisfied: httpcore==1.* in /usr/local/lib/python3.11/dist-packages (from httpx~=0.27->python-telegram-bot) (1.0.9)\n",
            "Requirement already satisfied: idna in /usr/local/lib/python3.11/dist-packages (from httpx~=0.27->python-telegram-bot) (3.10)\n",
            "Requirement already satisfied: h11>=0.16 in /usr/local/lib/python3.11/dist-packages (from httpcore==1.*->httpx~=0.27->python-telegram-bot) (0.16.0)\n",
            "Requirement already satisfied: sniffio>=1.1 in /usr/local/lib/python3.11/dist-packages (from anyio->httpx~=0.27->python-telegram-bot) (1.3.1)\n",
            "Requirement already satisfied: typing_extensions>=4.5 in /usr/local/lib/python3.11/dist-packages (from anyio->httpx~=0.27->python-telegram-bot) (4.13.2)\n",
            "Downloading python_telegram_bot-22.1-py3-none-any.whl (702 kB)\n",
            "\u001b[2K   \u001b[90m━━━━━━━━━━━━━━━━━━━━━━━━━━━━━━━━━━━━━━━━\u001b[0m \u001b[32m702.3/702.3 kB\u001b[0m \u001b[31m10.1 MB/s\u001b[0m eta \u001b[36m0:00:00\u001b[0m\n",
            "\u001b[?25hInstalling collected packages: python-telegram-bot\n",
            "Successfully installed python-telegram-bot-22.1\n"
          ]
        }
      ],
      "source": [
        "!pip install python-telegram-bot"
      ]
    },
    {
      "cell_type": "code",
      "execution_count": null,
      "metadata": {
        "colab": {
          "base_uri": "https://localhost:8080/",
          "height": 1000
        },
        "id": "HC7OBZT2L5Y5",
        "outputId": "6fe7ddd2-a4d8-47f0-e484-a53f5c3147d0"
      },
      "outputs": [
        {
          "name": "stderr",
          "output_type": "stream",
          "text": [
            "ERROR:telegram.ext.Application:No error handlers are registered, logging exception.\n",
            "Traceback (most recent call last):\n",
            "  File \"/usr/local/lib/python3.11/dist-packages/telegram/ext/_utils/networkloop.py\", line 115, in network_retry_loop\n",
            "    if not await do_action():\n",
            "           ^^^^^^^^^^^^^^^^^\n",
            "  File \"/usr/local/lib/python3.11/dist-packages/telegram/ext/_utils/networkloop.py\", line 108, in do_action\n",
            "    return action_cb_task.result()\n",
            "           ^^^^^^^^^^^^^^^^^^^^^^^\n",
            "  File \"/usr/lib/python3.11/asyncio/futures.py\", line 203, in result\n",
            "    raise self._exception.with_traceback(self._exception_tb)\n",
            "  File \"/usr/lib/python3.11/asyncio/tasks.py\", line 277, in __step\n",
            "    result = coro.send(None)\n",
            "             ^^^^^^^^^^^^^^^\n",
            "  File \"/usr/local/lib/python3.11/dist-packages/telegram/ext/_updater.py\", line 335, in polling_action_cb\n",
            "    updates = await self.bot.get_updates(\n",
            "              ^^^^^^^^^^^^^^^^^^^^^^^^^^^\n",
            "  File \"/usr/local/lib/python3.11/dist-packages/telegram/ext/_extbot.py\", line 669, in get_updates\n",
            "    updates = await super().get_updates(\n",
            "              ^^^^^^^^^^^^^^^^^^^^^^^^^^\n",
            "  File \"/usr/local/lib/python3.11/dist-packages/telegram/_bot.py\", line 4601, in get_updates\n",
            "    await self._post(\n",
            "  File \"/usr/local/lib/python3.11/dist-packages/telegram/_bot.py\", line 697, in _post\n",
            "    return await self._do_post(\n",
            "           ^^^^^^^^^^^^^^^^^^^^\n",
            "  File \"/usr/local/lib/python3.11/dist-packages/telegram/ext/_extbot.py\", line 369, in _do_post\n",
            "    return await super()._do_post(\n",
            "           ^^^^^^^^^^^^^^^^^^^^^^^\n",
            "  File \"/usr/local/lib/python3.11/dist-packages/telegram/_bot.py\", line 726, in _do_post\n",
            "    result = await request.post(\n",
            "             ^^^^^^^^^^^^^^^^^^^\n",
            "  File \"/usr/local/lib/python3.11/dist-packages/telegram/request/_baserequest.py\", line 197, in post\n",
            "    result = await self._request_wrapper(\n",
            "             ^^^^^^^^^^^^^^^^^^^^^^^^^^^^\n",
            "  File \"/usr/local/lib/python3.11/dist-packages/telegram/request/_baserequest.py\", line 355, in _request_wrapper\n",
            "    raise Conflict(message)\n",
            "telegram.error.Conflict: Conflict: terminated by other getUpdates request; make sure that only one bot instance is running\n",
            "WARNING:__main__:업데이트 None에서 오류가 발생했습니다: Conflict: terminated by other getUpdates request; make sure that only one bot instance is running\n",
            "ERROR:telegram.ext.Application:No error handlers are registered, logging exception.\n",
            "Traceback (most recent call last):\n",
            "  File \"/usr/local/lib/python3.11/dist-packages/telegram/ext/_utils/networkloop.py\", line 115, in network_retry_loop\n",
            "    if not await do_action():\n",
            "           ^^^^^^^^^^^^^^^^^\n",
            "  File \"/usr/local/lib/python3.11/dist-packages/telegram/ext/_utils/networkloop.py\", line 108, in do_action\n",
            "    return action_cb_task.result()\n",
            "           ^^^^^^^^^^^^^^^^^^^^^^^\n",
            "  File \"/usr/lib/python3.11/asyncio/futures.py\", line 203, in result\n",
            "    raise self._exception.with_traceback(self._exception_tb)\n",
            "  File \"/usr/lib/python3.11/asyncio/tasks.py\", line 277, in __step\n",
            "    result = coro.send(None)\n",
            "             ^^^^^^^^^^^^^^^\n",
            "  File \"/usr/local/lib/python3.11/dist-packages/telegram/ext/_updater.py\", line 335, in polling_action_cb\n",
            "    updates = await self.bot.get_updates(\n",
            "              ^^^^^^^^^^^^^^^^^^^^^^^^^^^\n",
            "  File \"/usr/local/lib/python3.11/dist-packages/telegram/ext/_extbot.py\", line 669, in get_updates\n",
            "    updates = await super().get_updates(\n",
            "              ^^^^^^^^^^^^^^^^^^^^^^^^^^\n",
            "  File \"/usr/local/lib/python3.11/dist-packages/telegram/_bot.py\", line 4601, in get_updates\n",
            "    await self._post(\n",
            "  File \"/usr/local/lib/python3.11/dist-packages/telegram/_bot.py\", line 697, in _post\n",
            "    return await self._do_post(\n",
            "           ^^^^^^^^^^^^^^^^^^^^\n",
            "  File \"/usr/local/lib/python3.11/dist-packages/telegram/ext/_extbot.py\", line 369, in _do_post\n",
            "    return await super()._do_post(\n",
            "           ^^^^^^^^^^^^^^^^^^^^^^^\n",
            "  File \"/usr/local/lib/python3.11/dist-packages/telegram/_bot.py\", line 726, in _do_post\n",
            "    result = await request.post(\n",
            "             ^^^^^^^^^^^^^^^^^^^\n",
            "  File \"/usr/local/lib/python3.11/dist-packages/telegram/request/_baserequest.py\", line 197, in post\n",
            "    result = await self._request_wrapper(\n",
            "             ^^^^^^^^^^^^^^^^^^^^^^^^^^^^\n",
            "  File \"/usr/local/lib/python3.11/dist-packages/telegram/request/_baserequest.py\", line 355, in _request_wrapper\n",
            "    raise Conflict(message)\n",
            "telegram.error.Conflict: Conflict: terminated by other getUpdates request; make sure that only one bot instance is running\n",
            "WARNING:__main__:업데이트 None에서 오류가 발생했습니다: Conflict: terminated by other getUpdates request; make sure that only one bot instance is running\n",
            "ERROR:telegram.ext.Application:No error handlers are registered, logging exception.\n",
            "Traceback (most recent call last):\n",
            "  File \"/usr/local/lib/python3.11/dist-packages/telegram/ext/_utils/networkloop.py\", line 115, in network_retry_loop\n",
            "    if not await do_action():\n",
            "           ^^^^^^^^^^^^^^^^^\n",
            "  File \"/usr/local/lib/python3.11/dist-packages/telegram/ext/_utils/networkloop.py\", line 108, in do_action\n",
            "    return action_cb_task.result()\n",
            "           ^^^^^^^^^^^^^^^^^^^^^^^\n",
            "  File \"/usr/lib/python3.11/asyncio/futures.py\", line 203, in result\n",
            "    raise self._exception.with_traceback(self._exception_tb)\n",
            "  File \"/usr/lib/python3.11/asyncio/tasks.py\", line 277, in __step\n",
            "    result = coro.send(None)\n",
            "             ^^^^^^^^^^^^^^^\n",
            "  File \"/usr/local/lib/python3.11/dist-packages/telegram/ext/_updater.py\", line 335, in polling_action_cb\n",
            "    updates = await self.bot.get_updates(\n",
            "              ^^^^^^^^^^^^^^^^^^^^^^^^^^^\n",
            "  File \"/usr/local/lib/python3.11/dist-packages/telegram/ext/_extbot.py\", line 669, in get_updates\n",
            "    updates = await super().get_updates(\n",
            "              ^^^^^^^^^^^^^^^^^^^^^^^^^^\n",
            "  File \"/usr/local/lib/python3.11/dist-packages/telegram/_bot.py\", line 4601, in get_updates\n",
            "    await self._post(\n",
            "  File \"/usr/local/lib/python3.11/dist-packages/telegram/_bot.py\", line 697, in _post\n",
            "    return await self._do_post(\n",
            "           ^^^^^^^^^^^^^^^^^^^^\n",
            "  File \"/usr/local/lib/python3.11/dist-packages/telegram/ext/_extbot.py\", line 369, in _do_post\n",
            "    return await super()._do_post(\n",
            "           ^^^^^^^^^^^^^^^^^^^^^^^\n",
            "  File \"/usr/local/lib/python3.11/dist-packages/telegram/_bot.py\", line 726, in _do_post\n",
            "    result = await request.post(\n",
            "             ^^^^^^^^^^^^^^^^^^^\n",
            "  File \"/usr/local/lib/python3.11/dist-packages/telegram/request/_baserequest.py\", line 197, in post\n",
            "    result = await self._request_wrapper(\n",
            "             ^^^^^^^^^^^^^^^^^^^^^^^^^^^^\n",
            "  File \"/usr/local/lib/python3.11/dist-packages/telegram/request/_baserequest.py\", line 355, in _request_wrapper\n",
            "    raise Conflict(message)\n",
            "telegram.error.Conflict: Conflict: terminated by other getUpdates request; make sure that only one bot instance is running\n",
            "WARNING:__main__:업데이트 None에서 오류가 발생했습니다: Conflict: terminated by other getUpdates request; make sure that only one bot instance is running\n",
            "ERROR:telegram.ext.Application:No error handlers are registered, logging exception.\n",
            "Traceback (most recent call last):\n",
            "  File \"/usr/local/lib/python3.11/dist-packages/telegram/ext/_utils/networkloop.py\", line 115, in network_retry_loop\n",
            "    if not await do_action():\n",
            "           ^^^^^^^^^^^^^^^^^\n",
            "  File \"/usr/local/lib/python3.11/dist-packages/telegram/ext/_utils/networkloop.py\", line 108, in do_action\n",
            "    return action_cb_task.result()\n",
            "           ^^^^^^^^^^^^^^^^^^^^^^^\n",
            "  File \"/usr/lib/python3.11/asyncio/futures.py\", line 203, in result\n",
            "    raise self._exception.with_traceback(self._exception_tb)\n",
            "  File \"/usr/lib/python3.11/asyncio/tasks.py\", line 277, in __step\n",
            "    result = coro.send(None)\n",
            "             ^^^^^^^^^^^^^^^\n",
            "  File \"/usr/local/lib/python3.11/dist-packages/telegram/ext/_updater.py\", line 335, in polling_action_cb\n",
            "    updates = await self.bot.get_updates(\n",
            "              ^^^^^^^^^^^^^^^^^^^^^^^^^^^\n",
            "  File \"/usr/local/lib/python3.11/dist-packages/telegram/ext/_extbot.py\", line 669, in get_updates\n",
            "    updates = await super().get_updates(\n",
            "              ^^^^^^^^^^^^^^^^^^^^^^^^^^\n",
            "  File \"/usr/local/lib/python3.11/dist-packages/telegram/_bot.py\", line 4601, in get_updates\n",
            "    await self._post(\n",
            "  File \"/usr/local/lib/python3.11/dist-packages/telegram/_bot.py\", line 697, in _post\n",
            "    return await self._do_post(\n",
            "           ^^^^^^^^^^^^^^^^^^^^\n",
            "  File \"/usr/local/lib/python3.11/dist-packages/telegram/ext/_extbot.py\", line 369, in _do_post\n",
            "    return await super()._do_post(\n",
            "           ^^^^^^^^^^^^^^^^^^^^^^^\n",
            "  File \"/usr/local/lib/python3.11/dist-packages/telegram/_bot.py\", line 726, in _do_post\n",
            "    result = await request.post(\n",
            "             ^^^^^^^^^^^^^^^^^^^\n",
            "  File \"/usr/local/lib/python3.11/dist-packages/telegram/request/_baserequest.py\", line 197, in post\n",
            "    result = await self._request_wrapper(\n",
            "             ^^^^^^^^^^^^^^^^^^^^^^^^^^^^\n",
            "  File \"/usr/local/lib/python3.11/dist-packages/telegram/request/_baserequest.py\", line 355, in _request_wrapper\n",
            "    raise Conflict(message)\n",
            "telegram.error.Conflict: Conflict: terminated by other getUpdates request; make sure that only one bot instance is running\n",
            "WARNING:__main__:업데이트 None에서 오류가 발생했습니다: Conflict: terminated by other getUpdates request; make sure that only one bot instance is running\n",
            "ERROR:telegram.ext.Application:No error handlers are registered, logging exception.\n",
            "Traceback (most recent call last):\n",
            "  File \"/usr/local/lib/python3.11/dist-packages/telegram/ext/_utils/networkloop.py\", line 115, in network_retry_loop\n",
            "    if not await do_action():\n",
            "           ^^^^^^^^^^^^^^^^^\n",
            "  File \"/usr/local/lib/python3.11/dist-packages/telegram/ext/_utils/networkloop.py\", line 108, in do_action\n",
            "    return action_cb_task.result()\n",
            "           ^^^^^^^^^^^^^^^^^^^^^^^\n",
            "  File \"/usr/lib/python3.11/asyncio/futures.py\", line 203, in result\n",
            "    raise self._exception.with_traceback(self._exception_tb)\n",
            "  File \"/usr/lib/python3.11/asyncio/tasks.py\", line 277, in __step\n",
            "    result = coro.send(None)\n",
            "             ^^^^^^^^^^^^^^^\n",
            "  File \"/usr/local/lib/python3.11/dist-packages/telegram/ext/_updater.py\", line 335, in polling_action_cb\n",
            "    updates = await self.bot.get_updates(\n",
            "              ^^^^^^^^^^^^^^^^^^^^^^^^^^^\n",
            "  File \"/usr/local/lib/python3.11/dist-packages/telegram/ext/_extbot.py\", line 669, in get_updates\n",
            "    updates = await super().get_updates(\n",
            "              ^^^^^^^^^^^^^^^^^^^^^^^^^^\n",
            "  File \"/usr/local/lib/python3.11/dist-packages/telegram/_bot.py\", line 4601, in get_updates\n",
            "    await self._post(\n",
            "  File \"/usr/local/lib/python3.11/dist-packages/telegram/_bot.py\", line 697, in _post\n",
            "    return await self._do_post(\n",
            "           ^^^^^^^^^^^^^^^^^^^^\n",
            "  File \"/usr/local/lib/python3.11/dist-packages/telegram/ext/_extbot.py\", line 369, in _do_post\n",
            "    return await super()._do_post(\n",
            "           ^^^^^^^^^^^^^^^^^^^^^^^\n",
            "  File \"/usr/local/lib/python3.11/dist-packages/telegram/_bot.py\", line 726, in _do_post\n",
            "    result = await request.post(\n",
            "             ^^^^^^^^^^^^^^^^^^^\n",
            "  File \"/usr/local/lib/python3.11/dist-packages/telegram/request/_baserequest.py\", line 197, in post\n",
            "    result = await self._request_wrapper(\n",
            "             ^^^^^^^^^^^^^^^^^^^^^^^^^^^^\n",
            "  File \"/usr/local/lib/python3.11/dist-packages/telegram/request/_baserequest.py\", line 355, in _request_wrapper\n",
            "    raise Conflict(message)\n",
            "telegram.error.Conflict: Conflict: terminated by other getUpdates request; make sure that only one bot instance is running\n",
            "WARNING:__main__:업데이트 None에서 오류가 발생했습니다: Conflict: terminated by other getUpdates request; make sure that only one bot instance is running\n",
            "ERROR:telegram.ext.Application:No error handlers are registered, logging exception.\n",
            "Traceback (most recent call last):\n",
            "  File \"/usr/local/lib/python3.11/dist-packages/telegram/ext/_utils/networkloop.py\", line 115, in network_retry_loop\n",
            "    if not await do_action():\n",
            "           ^^^^^^^^^^^^^^^^^\n",
            "  File \"/usr/local/lib/python3.11/dist-packages/telegram/ext/_utils/networkloop.py\", line 108, in do_action\n",
            "    return action_cb_task.result()\n",
            "           ^^^^^^^^^^^^^^^^^^^^^^^\n",
            "  File \"/usr/lib/python3.11/asyncio/futures.py\", line 203, in result\n",
            "    raise self._exception.with_traceback(self._exception_tb)\n",
            "  File \"/usr/lib/python3.11/asyncio/tasks.py\", line 277, in __step\n",
            "    result = coro.send(None)\n",
            "             ^^^^^^^^^^^^^^^\n",
            "  File \"/usr/local/lib/python3.11/dist-packages/telegram/ext/_updater.py\", line 335, in polling_action_cb\n",
            "    updates = await self.bot.get_updates(\n",
            "              ^^^^^^^^^^^^^^^^^^^^^^^^^^^\n",
            "  File \"/usr/local/lib/python3.11/dist-packages/telegram/ext/_extbot.py\", line 669, in get_updates\n",
            "    updates = await super().get_updates(\n",
            "              ^^^^^^^^^^^^^^^^^^^^^^^^^^\n",
            "  File \"/usr/local/lib/python3.11/dist-packages/telegram/_bot.py\", line 4601, in get_updates\n",
            "    await self._post(\n",
            "  File \"/usr/local/lib/python3.11/dist-packages/telegram/_bot.py\", line 697, in _post\n",
            "    return await self._do_post(\n",
            "           ^^^^^^^^^^^^^^^^^^^^\n",
            "  File \"/usr/local/lib/python3.11/dist-packages/telegram/ext/_extbot.py\", line 369, in _do_post\n",
            "    return await super()._do_post(\n",
            "           ^^^^^^^^^^^^^^^^^^^^^^^\n",
            "  File \"/usr/local/lib/python3.11/dist-packages/telegram/_bot.py\", line 726, in _do_post\n",
            "    result = await request.post(\n",
            "             ^^^^^^^^^^^^^^^^^^^\n",
            "  File \"/usr/local/lib/python3.11/dist-packages/telegram/request/_baserequest.py\", line 197, in post\n",
            "    result = await self._request_wrapper(\n",
            "             ^^^^^^^^^^^^^^^^^^^^^^^^^^^^\n",
            "  File \"/usr/local/lib/python3.11/dist-packages/telegram/request/_baserequest.py\", line 355, in _request_wrapper\n",
            "    raise Conflict(message)\n",
            "telegram.error.Conflict: Conflict: terminated by other getUpdates request; make sure that only one bot instance is running\n",
            "WARNING:__main__:업데이트 None에서 오류가 발생했습니다: Conflict: terminated by other getUpdates request; make sure that only one bot instance is running\n",
            "ERROR:telegram.ext.Application:No error handlers are registered, logging exception.\n",
            "Traceback (most recent call last):\n",
            "  File \"/usr/local/lib/python3.11/dist-packages/telegram/ext/_utils/networkloop.py\", line 115, in network_retry_loop\n",
            "    if not await do_action():\n",
            "           ^^^^^^^^^^^^^^^^^\n",
            "  File \"/usr/local/lib/python3.11/dist-packages/telegram/ext/_utils/networkloop.py\", line 108, in do_action\n",
            "    return action_cb_task.result()\n",
            "           ^^^^^^^^^^^^^^^^^^^^^^^\n",
            "  File \"/usr/lib/python3.11/asyncio/futures.py\", line 203, in result\n",
            "    raise self._exception.with_traceback(self._exception_tb)\n",
            "  File \"/usr/lib/python3.11/asyncio/tasks.py\", line 277, in __step\n",
            "    result = coro.send(None)\n",
            "             ^^^^^^^^^^^^^^^\n",
            "  File \"/usr/local/lib/python3.11/dist-packages/telegram/ext/_updater.py\", line 335, in polling_action_cb\n",
            "    updates = await self.bot.get_updates(\n",
            "              ^^^^^^^^^^^^^^^^^^^^^^^^^^^\n",
            "  File \"/usr/local/lib/python3.11/dist-packages/telegram/ext/_extbot.py\", line 669, in get_updates\n",
            "    updates = await super().get_updates(\n",
            "              ^^^^^^^^^^^^^^^^^^^^^^^^^^\n",
            "  File \"/usr/local/lib/python3.11/dist-packages/telegram/_bot.py\", line 4601, in get_updates\n",
            "    await self._post(\n",
            "  File \"/usr/local/lib/python3.11/dist-packages/telegram/_bot.py\", line 697, in _post\n",
            "    return await self._do_post(\n",
            "           ^^^^^^^^^^^^^^^^^^^^\n",
            "  File \"/usr/local/lib/python3.11/dist-packages/telegram/ext/_extbot.py\", line 369, in _do_post\n",
            "    return await super()._do_post(\n",
            "           ^^^^^^^^^^^^^^^^^^^^^^^\n",
            "  File \"/usr/local/lib/python3.11/dist-packages/telegram/_bot.py\", line 726, in _do_post\n",
            "    result = await request.post(\n",
            "             ^^^^^^^^^^^^^^^^^^^\n",
            "  File \"/usr/local/lib/python3.11/dist-packages/telegram/request/_baserequest.py\", line 197, in post\n",
            "    result = await self._request_wrapper(\n",
            "             ^^^^^^^^^^^^^^^^^^^^^^^^^^^^\n",
            "  File \"/usr/local/lib/python3.11/dist-packages/telegram/request/_baserequest.py\", line 355, in _request_wrapper\n",
            "    raise Conflict(message)\n",
            "telegram.error.Conflict: Conflict: terminated by other getUpdates request; make sure that only one bot instance is running\n",
            "WARNING:__main__:업데이트 None에서 오류가 발생했습니다: Conflict: terminated by other getUpdates request; make sure that only one bot instance is running\n",
            "ERROR:telegram.ext.Application:No error handlers are registered, logging exception.\n",
            "Traceback (most recent call last):\n",
            "  File \"/usr/local/lib/python3.11/dist-packages/telegram/ext/_utils/networkloop.py\", line 115, in network_retry_loop\n",
            "    if not await do_action():\n",
            "           ^^^^^^^^^^^^^^^^^\n",
            "  File \"/usr/local/lib/python3.11/dist-packages/telegram/ext/_utils/networkloop.py\", line 108, in do_action\n",
            "    return action_cb_task.result()\n",
            "           ^^^^^^^^^^^^^^^^^^^^^^^\n",
            "  File \"/usr/lib/python3.11/asyncio/futures.py\", line 203, in result\n",
            "    raise self._exception.with_traceback(self._exception_tb)\n",
            "  File \"/usr/lib/python3.11/asyncio/tasks.py\", line 277, in __step\n",
            "    result = coro.send(None)\n",
            "             ^^^^^^^^^^^^^^^\n",
            "  File \"/usr/local/lib/python3.11/dist-packages/telegram/ext/_updater.py\", line 335, in polling_action_cb\n",
            "    updates = await self.bot.get_updates(\n",
            "              ^^^^^^^^^^^^^^^^^^^^^^^^^^^\n",
            "  File \"/usr/local/lib/python3.11/dist-packages/telegram/ext/_extbot.py\", line 669, in get_updates\n",
            "    updates = await super().get_updates(\n",
            "              ^^^^^^^^^^^^^^^^^^^^^^^^^^\n",
            "  File \"/usr/local/lib/python3.11/dist-packages/telegram/_bot.py\", line 4601, in get_updates\n",
            "    await self._post(\n",
            "  File \"/usr/local/lib/python3.11/dist-packages/telegram/_bot.py\", line 697, in _post\n",
            "    return await self._do_post(\n",
            "           ^^^^^^^^^^^^^^^^^^^^\n",
            "  File \"/usr/local/lib/python3.11/dist-packages/telegram/ext/_extbot.py\", line 369, in _do_post\n",
            "    return await super()._do_post(\n",
            "           ^^^^^^^^^^^^^^^^^^^^^^^\n",
            "  File \"/usr/local/lib/python3.11/dist-packages/telegram/_bot.py\", line 726, in _do_post\n",
            "    result = await request.post(\n",
            "             ^^^^^^^^^^^^^^^^^^^\n",
            "  File \"/usr/local/lib/python3.11/dist-packages/telegram/request/_baserequest.py\", line 197, in post\n",
            "    result = await self._request_wrapper(\n",
            "             ^^^^^^^^^^^^^^^^^^^^^^^^^^^^\n",
            "  File \"/usr/local/lib/python3.11/dist-packages/telegram/request/_baserequest.py\", line 355, in _request_wrapper\n",
            "    raise Conflict(message)\n",
            "telegram.error.Conflict: Conflict: terminated by other getUpdates request; make sure that only one bot instance is running\n",
            "WARNING:__main__:업데이트 None에서 오류가 발생했습니다: Conflict: terminated by other getUpdates request; make sure that only one bot instance is running\n",
            "ERROR:telegram.ext.Application:No error handlers are registered, logging exception.\n",
            "Traceback (most recent call last):\n",
            "  File \"/usr/local/lib/python3.11/dist-packages/telegram/ext/_utils/networkloop.py\", line 115, in network_retry_loop\n",
            "    if not await do_action():\n",
            "           ^^^^^^^^^^^^^^^^^\n",
            "  File \"/usr/local/lib/python3.11/dist-packages/telegram/ext/_utils/networkloop.py\", line 108, in do_action\n",
            "    return action_cb_task.result()\n",
            "           ^^^^^^^^^^^^^^^^^^^^^^^\n",
            "  File \"/usr/lib/python3.11/asyncio/futures.py\", line 203, in result\n",
            "    raise self._exception.with_traceback(self._exception_tb)\n",
            "  File \"/usr/lib/python3.11/asyncio/tasks.py\", line 277, in __step\n",
            "    result = coro.send(None)\n",
            "             ^^^^^^^^^^^^^^^\n",
            "  File \"/usr/local/lib/python3.11/dist-packages/telegram/ext/_updater.py\", line 335, in polling_action_cb\n",
            "    updates = await self.bot.get_updates(\n",
            "              ^^^^^^^^^^^^^^^^^^^^^^^^^^^\n",
            "  File \"/usr/local/lib/python3.11/dist-packages/telegram/ext/_extbot.py\", line 669, in get_updates\n",
            "    updates = await super().get_updates(\n",
            "              ^^^^^^^^^^^^^^^^^^^^^^^^^^\n",
            "  File \"/usr/local/lib/python3.11/dist-packages/telegram/_bot.py\", line 4601, in get_updates\n",
            "    await self._post(\n",
            "  File \"/usr/local/lib/python3.11/dist-packages/telegram/_bot.py\", line 697, in _post\n",
            "    return await self._do_post(\n",
            "           ^^^^^^^^^^^^^^^^^^^^\n",
            "  File \"/usr/local/lib/python3.11/dist-packages/telegram/ext/_extbot.py\", line 369, in _do_post\n",
            "    return await super()._do_post(\n",
            "           ^^^^^^^^^^^^^^^^^^^^^^^\n",
            "  File \"/usr/local/lib/python3.11/dist-packages/telegram/_bot.py\", line 726, in _do_post\n",
            "    result = await request.post(\n",
            "             ^^^^^^^^^^^^^^^^^^^\n",
            "  File \"/usr/local/lib/python3.11/dist-packages/telegram/request/_baserequest.py\", line 197, in post\n",
            "    result = await self._request_wrapper(\n",
            "             ^^^^^^^^^^^^^^^^^^^^^^^^^^^^\n",
            "  File \"/usr/local/lib/python3.11/dist-packages/telegram/request/_baserequest.py\", line 355, in _request_wrapper\n",
            "    raise Conflict(message)\n",
            "telegram.error.Conflict: Conflict: terminated by other getUpdates request; make sure that only one bot instance is running\n"
          ]
        },
        {
          "ename": "RuntimeError",
          "evalue": "Cannot close a running event loop",
          "output_type": "error",
          "traceback": [
            "\u001b[0;31m---------------------------------------------------------------------------\u001b[0m",
            "\u001b[0;31mRuntimeError\u001b[0m                              Traceback (most recent call last)",
            "\u001b[0;32m<ipython-input-70-f5db9bcd1ad6>\u001b[0m in \u001b[0;36m<cell line: 0>\u001b[0;34m()\u001b[0m\n\u001b[1;32m    333\u001b[0m \u001b[0;32mif\u001b[0m \u001b[0m__name__\u001b[0m \u001b[0;34m==\u001b[0m \u001b[0;34m\"__main__\"\u001b[0m\u001b[0;34m:\u001b[0m\u001b[0;34m\u001b[0m\u001b[0;34m\u001b[0m\u001b[0m\n\u001b[1;32m    334\u001b[0m     \u001b[0;32mimport\u001b[0m \u001b[0masyncio\u001b[0m\u001b[0;34m\u001b[0m\u001b[0;34m\u001b[0m\u001b[0m\n\u001b[0;32m--> 335\u001b[0;31m     \u001b[0masyncio\u001b[0m\u001b[0;34m.\u001b[0m\u001b[0mrun\u001b[0m\u001b[0;34m(\u001b[0m\u001b[0mmain\u001b[0m\u001b[0;34m(\u001b[0m\u001b[0;34m)\u001b[0m\u001b[0;34m)\u001b[0m\u001b[0;34m\u001b[0m\u001b[0;34m\u001b[0m\u001b[0m\n\u001b[0m",
            "\u001b[0;32m/usr/local/lib/python3.11/dist-packages/nest_asyncio.py\u001b[0m in \u001b[0;36mrun\u001b[0;34m(main, debug)\u001b[0m\n\u001b[1;32m     28\u001b[0m         \u001b[0mtask\u001b[0m \u001b[0;34m=\u001b[0m \u001b[0masyncio\u001b[0m\u001b[0;34m.\u001b[0m\u001b[0mensure_future\u001b[0m\u001b[0;34m(\u001b[0m\u001b[0mmain\u001b[0m\u001b[0;34m)\u001b[0m\u001b[0;34m\u001b[0m\u001b[0;34m\u001b[0m\u001b[0m\n\u001b[1;32m     29\u001b[0m         \u001b[0;32mtry\u001b[0m\u001b[0;34m:\u001b[0m\u001b[0;34m\u001b[0m\u001b[0;34m\u001b[0m\u001b[0m\n\u001b[0;32m---> 30\u001b[0;31m             \u001b[0;32mreturn\u001b[0m \u001b[0mloop\u001b[0m\u001b[0;34m.\u001b[0m\u001b[0mrun_until_complete\u001b[0m\u001b[0;34m(\u001b[0m\u001b[0mtask\u001b[0m\u001b[0;34m)\u001b[0m\u001b[0;34m\u001b[0m\u001b[0;34m\u001b[0m\u001b[0m\n\u001b[0m\u001b[1;32m     31\u001b[0m         \u001b[0;32mfinally\u001b[0m\u001b[0;34m:\u001b[0m\u001b[0;34m\u001b[0m\u001b[0;34m\u001b[0m\u001b[0m\n\u001b[1;32m     32\u001b[0m             \u001b[0;32mif\u001b[0m \u001b[0;32mnot\u001b[0m \u001b[0mtask\u001b[0m\u001b[0;34m.\u001b[0m\u001b[0mdone\u001b[0m\u001b[0;34m(\u001b[0m\u001b[0;34m)\u001b[0m\u001b[0;34m:\u001b[0m\u001b[0;34m\u001b[0m\u001b[0;34m\u001b[0m\u001b[0m\n",
            "\u001b[0;32m/usr/local/lib/python3.11/dist-packages/nest_asyncio.py\u001b[0m in \u001b[0;36mrun_until_complete\u001b[0;34m(self, future)\u001b[0m\n\u001b[1;32m     96\u001b[0m                 raise RuntimeError(\n\u001b[1;32m     97\u001b[0m                     'Event loop stopped before Future completed.')\n\u001b[0;32m---> 98\u001b[0;31m             \u001b[0;32mreturn\u001b[0m \u001b[0mf\u001b[0m\u001b[0;34m.\u001b[0m\u001b[0mresult\u001b[0m\u001b[0;34m(\u001b[0m\u001b[0;34m)\u001b[0m\u001b[0;34m\u001b[0m\u001b[0;34m\u001b[0m\u001b[0m\n\u001b[0m\u001b[1;32m     99\u001b[0m \u001b[0;34m\u001b[0m\u001b[0m\n\u001b[1;32m    100\u001b[0m     \u001b[0;32mdef\u001b[0m \u001b[0m_run_once\u001b[0m\u001b[0;34m(\u001b[0m\u001b[0mself\u001b[0m\u001b[0;34m)\u001b[0m\u001b[0;34m:\u001b[0m\u001b[0;34m\u001b[0m\u001b[0;34m\u001b[0m\u001b[0m\n",
            "\u001b[0;32m/usr/lib/python3.11/asyncio/futures.py\u001b[0m in \u001b[0;36mresult\u001b[0;34m(self)\u001b[0m\n\u001b[1;32m    201\u001b[0m         \u001b[0mself\u001b[0m\u001b[0;34m.\u001b[0m\u001b[0m__log_traceback\u001b[0m \u001b[0;34m=\u001b[0m \u001b[0;32mFalse\u001b[0m\u001b[0;34m\u001b[0m\u001b[0;34m\u001b[0m\u001b[0m\n\u001b[1;32m    202\u001b[0m         \u001b[0;32mif\u001b[0m \u001b[0mself\u001b[0m\u001b[0;34m.\u001b[0m\u001b[0m_exception\u001b[0m \u001b[0;32mis\u001b[0m \u001b[0;32mnot\u001b[0m \u001b[0;32mNone\u001b[0m\u001b[0;34m:\u001b[0m\u001b[0;34m\u001b[0m\u001b[0;34m\u001b[0m\u001b[0m\n\u001b[0;32m--> 203\u001b[0;31m             \u001b[0;32mraise\u001b[0m \u001b[0mself\u001b[0m\u001b[0;34m.\u001b[0m\u001b[0m_exception\u001b[0m\u001b[0;34m.\u001b[0m\u001b[0mwith_traceback\u001b[0m\u001b[0;34m(\u001b[0m\u001b[0mself\u001b[0m\u001b[0;34m.\u001b[0m\u001b[0m_exception_tb\u001b[0m\u001b[0;34m)\u001b[0m\u001b[0;34m\u001b[0m\u001b[0;34m\u001b[0m\u001b[0m\n\u001b[0m\u001b[1;32m    204\u001b[0m         \u001b[0;32mreturn\u001b[0m \u001b[0mself\u001b[0m\u001b[0;34m.\u001b[0m\u001b[0m_result\u001b[0m\u001b[0;34m\u001b[0m\u001b[0;34m\u001b[0m\u001b[0m\n\u001b[1;32m    205\u001b[0m \u001b[0;34m\u001b[0m\u001b[0m\n",
            "\u001b[0;32m/usr/lib/python3.11/asyncio/tasks.py\u001b[0m in \u001b[0;36m__step\u001b[0;34m(***failed resolving arguments***)\u001b[0m\n\u001b[1;32m    275\u001b[0m                 \u001b[0;31m# We use the `send` method directly, because coroutines\u001b[0m\u001b[0;34m\u001b[0m\u001b[0;34m\u001b[0m\u001b[0m\n\u001b[1;32m    276\u001b[0m                 \u001b[0;31m# don't have `__iter__` and `__next__` methods.\u001b[0m\u001b[0;34m\u001b[0m\u001b[0;34m\u001b[0m\u001b[0m\n\u001b[0;32m--> 277\u001b[0;31m                 \u001b[0mresult\u001b[0m \u001b[0;34m=\u001b[0m \u001b[0mcoro\u001b[0m\u001b[0;34m.\u001b[0m\u001b[0msend\u001b[0m\u001b[0;34m(\u001b[0m\u001b[0;32mNone\u001b[0m\u001b[0;34m)\u001b[0m\u001b[0;34m\u001b[0m\u001b[0;34m\u001b[0m\u001b[0m\n\u001b[0m\u001b[1;32m    278\u001b[0m             \u001b[0;32melse\u001b[0m\u001b[0;34m:\u001b[0m\u001b[0;34m\u001b[0m\u001b[0;34m\u001b[0m\u001b[0m\n\u001b[1;32m    279\u001b[0m                 \u001b[0mresult\u001b[0m \u001b[0;34m=\u001b[0m \u001b[0mcoro\u001b[0m\u001b[0;34m.\u001b[0m\u001b[0mthrow\u001b[0m\u001b[0;34m(\u001b[0m\u001b[0mexc\u001b[0m\u001b[0;34m)\u001b[0m\u001b[0;34m\u001b[0m\u001b[0;34m\u001b[0m\u001b[0m\n",
            "\u001b[0;32m<ipython-input-70-f5db9bcd1ad6>\u001b[0m in \u001b[0;36mmain\u001b[0;34m()\u001b[0m\n\u001b[1;32m    327\u001b[0m \u001b[0;34m\u001b[0m\u001b[0m\n\u001b[1;32m    328\u001b[0m     \u001b[0mlogger\u001b[0m\u001b[0;34m.\u001b[0m\u001b[0minfo\u001b[0m\u001b[0;34m(\u001b[0m\u001b[0;34m\"봇을 시작합니다...\"\u001b[0m\u001b[0;34m)\u001b[0m\u001b[0;34m\u001b[0m\u001b[0;34m\u001b[0m\u001b[0m\n\u001b[0;32m--> 329\u001b[0;31m     \u001b[0;32mawait\u001b[0m \u001b[0mapplication\u001b[0m\u001b[0;34m.\u001b[0m\u001b[0mrun_polling\u001b[0m\u001b[0;34m(\u001b[0m\u001b[0mallowed_updates\u001b[0m\u001b[0;34m=\u001b[0m\u001b[0mUpdate\u001b[0m\u001b[0;34m.\u001b[0m\u001b[0mALL_TYPES\u001b[0m\u001b[0;34m)\u001b[0m\u001b[0;34m\u001b[0m\u001b[0;34m\u001b[0m\u001b[0m\n\u001b[0m\u001b[1;32m    330\u001b[0m     \u001b[0mlogger\u001b[0m\u001b[0;34m.\u001b[0m\u001b[0minfo\u001b[0m\u001b[0;34m(\u001b[0m\u001b[0;34m\"봇이 종료되었습니다.\"\u001b[0m\u001b[0;34m)\u001b[0m\u001b[0;34m\u001b[0m\u001b[0;34m\u001b[0m\u001b[0m\n\u001b[1;32m    331\u001b[0m \u001b[0;34m\u001b[0m\u001b[0m\n",
            "\u001b[0;32m/usr/local/lib/python3.11/dist-packages/telegram/ext/_application.py\u001b[0m in \u001b[0;36mrun_polling\u001b[0;34m(self, poll_interval, timeout, bootstrap_retries, allowed_updates, drop_pending_updates, close_loop, stop_signals)\u001b[0m\n\u001b[1;32m    830\u001b[0m             \u001b[0mself\u001b[0m\u001b[0;34m.\u001b[0m\u001b[0mcreate_task\u001b[0m\u001b[0;34m(\u001b[0m\u001b[0mself\u001b[0m\u001b[0;34m.\u001b[0m\u001b[0mprocess_error\u001b[0m\u001b[0;34m(\u001b[0m\u001b[0merror\u001b[0m\u001b[0;34m=\u001b[0m\u001b[0mexc\u001b[0m\u001b[0;34m,\u001b[0m \u001b[0mupdate\u001b[0m\u001b[0;34m=\u001b[0m\u001b[0;32mNone\u001b[0m\u001b[0;34m)\u001b[0m\u001b[0;34m)\u001b[0m\u001b[0;34m\u001b[0m\u001b[0;34m\u001b[0m\u001b[0m\n\u001b[1;32m    831\u001b[0m \u001b[0;34m\u001b[0m\u001b[0m\n\u001b[0;32m--> 832\u001b[0;31m         return self.__run(\n\u001b[0m\u001b[1;32m    833\u001b[0m             updater_coroutine=self.updater.start_polling(\n\u001b[1;32m    834\u001b[0m                 \u001b[0mpoll_interval\u001b[0m\u001b[0;34m=\u001b[0m\u001b[0mpoll_interval\u001b[0m\u001b[0;34m,\u001b[0m\u001b[0;34m\u001b[0m\u001b[0;34m\u001b[0m\u001b[0m\n",
            "\u001b[0;32m/usr/local/lib/python3.11/dist-packages/telegram/ext/_application.py\u001b[0m in \u001b[0;36m__run\u001b[0;34m(self, updater_coroutine, stop_signals, bootstrap_retries, close_loop)\u001b[0m\n\u001b[1;32m   1070\u001b[0m             \u001b[0;32mfinally\u001b[0m\u001b[0;34m:\u001b[0m\u001b[0;34m\u001b[0m\u001b[0;34m\u001b[0m\u001b[0m\n\u001b[1;32m   1071\u001b[0m                 \u001b[0;32mif\u001b[0m \u001b[0mclose_loop\u001b[0m\u001b[0;34m:\u001b[0m\u001b[0;34m\u001b[0m\u001b[0;34m\u001b[0m\u001b[0m\n\u001b[0;32m-> 1072\u001b[0;31m                     \u001b[0mloop\u001b[0m\u001b[0;34m.\u001b[0m\u001b[0mclose\u001b[0m\u001b[0;34m(\u001b[0m\u001b[0;34m)\u001b[0m\u001b[0;34m\u001b[0m\u001b[0;34m\u001b[0m\u001b[0m\n\u001b[0m\u001b[1;32m   1073\u001b[0m \u001b[0;34m\u001b[0m\u001b[0m\n\u001b[1;32m   1074\u001b[0m     def create_task(\n",
            "\u001b[0;32m/usr/lib/python3.11/asyncio/unix_events.py\u001b[0m in \u001b[0;36mclose\u001b[0;34m(self)\u001b[0m\n\u001b[1;32m     66\u001b[0m \u001b[0;34m\u001b[0m\u001b[0m\n\u001b[1;32m     67\u001b[0m     \u001b[0;32mdef\u001b[0m \u001b[0mclose\u001b[0m\u001b[0;34m(\u001b[0m\u001b[0mself\u001b[0m\u001b[0;34m)\u001b[0m\u001b[0;34m:\u001b[0m\u001b[0;34m\u001b[0m\u001b[0;34m\u001b[0m\u001b[0m\n\u001b[0;32m---> 68\u001b[0;31m         \u001b[0msuper\u001b[0m\u001b[0;34m(\u001b[0m\u001b[0;34m)\u001b[0m\u001b[0;34m.\u001b[0m\u001b[0mclose\u001b[0m\u001b[0;34m(\u001b[0m\u001b[0;34m)\u001b[0m\u001b[0;34m\u001b[0m\u001b[0;34m\u001b[0m\u001b[0m\n\u001b[0m\u001b[1;32m     69\u001b[0m         \u001b[0;32mif\u001b[0m \u001b[0;32mnot\u001b[0m \u001b[0msys\u001b[0m\u001b[0;34m.\u001b[0m\u001b[0mis_finalizing\u001b[0m\u001b[0;34m(\u001b[0m\u001b[0;34m)\u001b[0m\u001b[0;34m:\u001b[0m\u001b[0;34m\u001b[0m\u001b[0;34m\u001b[0m\u001b[0m\n\u001b[1;32m     70\u001b[0m             \u001b[0;32mfor\u001b[0m \u001b[0msig\u001b[0m \u001b[0;32min\u001b[0m \u001b[0mlist\u001b[0m\u001b[0;34m(\u001b[0m\u001b[0mself\u001b[0m\u001b[0;34m.\u001b[0m\u001b[0m_signal_handlers\u001b[0m\u001b[0;34m)\u001b[0m\u001b[0;34m:\u001b[0m\u001b[0;34m\u001b[0m\u001b[0;34m\u001b[0m\u001b[0m\n",
            "\u001b[0;32m/usr/lib/python3.11/asyncio/selector_events.py\u001b[0m in \u001b[0;36mclose\u001b[0;34m(self)\u001b[0m\n\u001b[1;32m     86\u001b[0m     \u001b[0;32mdef\u001b[0m \u001b[0mclose\u001b[0m\u001b[0;34m(\u001b[0m\u001b[0mself\u001b[0m\u001b[0;34m)\u001b[0m\u001b[0;34m:\u001b[0m\u001b[0;34m\u001b[0m\u001b[0;34m\u001b[0m\u001b[0m\n\u001b[1;32m     87\u001b[0m         \u001b[0;32mif\u001b[0m \u001b[0mself\u001b[0m\u001b[0;34m.\u001b[0m\u001b[0mis_running\u001b[0m\u001b[0;34m(\u001b[0m\u001b[0;34m)\u001b[0m\u001b[0;34m:\u001b[0m\u001b[0;34m\u001b[0m\u001b[0;34m\u001b[0m\u001b[0m\n\u001b[0;32m---> 88\u001b[0;31m             \u001b[0;32mraise\u001b[0m \u001b[0mRuntimeError\u001b[0m\u001b[0;34m(\u001b[0m\u001b[0;34m\"Cannot close a running event loop\"\u001b[0m\u001b[0;34m)\u001b[0m\u001b[0;34m\u001b[0m\u001b[0;34m\u001b[0m\u001b[0m\n\u001b[0m\u001b[1;32m     89\u001b[0m         \u001b[0;32mif\u001b[0m \u001b[0mself\u001b[0m\u001b[0;34m.\u001b[0m\u001b[0mis_closed\u001b[0m\u001b[0;34m(\u001b[0m\u001b[0;34m)\u001b[0m\u001b[0;34m:\u001b[0m\u001b[0;34m\u001b[0m\u001b[0;34m\u001b[0m\u001b[0m\n\u001b[1;32m     90\u001b[0m             \u001b[0;32mreturn\u001b[0m\u001b[0;34m\u001b[0m\u001b[0;34m\u001b[0m\u001b[0m\n",
            "\u001b[0;31mRuntimeError\u001b[0m: Cannot close a running event loop"
          ]
        }
      ],
      "source": [
        "\n",
        "import logging\n",
        "import httpx  # API 호출을 위한 라이브러리 임포트\n",
        "from telegram import Update\n",
        "from telegram.ext import Application, CommandHandler, MessageHandler, filters, ContextTypes\n",
        "import nest_asyncio\n",
        "import asyncio\n",
        "\n",
        "# 1. 봇 토큰 설정 (아까 BotFather에게서 받은 토큰을 여기에 붙여넣으세요!)\n",
        "TOKEN = \n",
        "\n",
        "# 로깅 설정\n",
        "logging.basicConfig(\n",
        "    format=\"%(asctime)s - %(name)s - %(levelname)s - %(message)s\", level=logging.INFO\n",
        ")\n",
        "logging.getLogger(\"httpx\").setLevel(logging.WARNING)\n",
        "logger = logging.getLogger(__name__)\n",
        "\n",
        "\n",
        "# --- 새로운 부분: API 호출 함수 정의 ---\n",
        "async def get_api_data() -> str:\n",
        "    \"\"\"\n",
        "    외부 API를 호출하여 데이터를 가져오는 비동기 함수.\n",
        "    이 함수는 예시이며, 실제 사용할 API에 맞게 수정해야 합니다.\n",
        "    \"\"\"\n",
        "    # **중요:** 여기에 실제 사용할 API의 URL과 필요한 API 키를 넣으세요.\n",
        "    # 이 예시는 OpenWeatherMap API의 대략적인 구조를 따릅니다.\n",
        "    # 실제 API 키는 반드시 발급받아야 합니다!\n",
        "    api_url = \"https://api.openweathermap.org/data/2.5/weather\"\n",
        "    city_name = \"Wonju\"  # 원하는 도시 이름\n",
        "    # **YOUR_OPENWEATHERMAP_API_KEY_HERE** 부분을 당신의 실제 API 키로 교체하세요!\n",
        "    api_key = #openweather api키\n",
        "\n",
        "    params = {\n",
        "        \"q\": city_name,\n",
        "        \"appid\": api_key,\n",
        "        \"units\": \"metric\",  # 섭씨 온도를 원하면 'metric', 화씨는 'imperial'\n",
        "        \"lang\": \"kr\"  # 한국어 설명을 원하면 'kr'\n",
        "    }\n",
        "\n",
        "    async with httpx.AsyncClient() as client:\n",
        "        try:\n",
        "            response = await client.get(api_url, params=params, timeout=10)  # 10초 타임아웃\n",
        "            response.raise_for_status()  # HTTP 오류 (4xx, 5xx)가 발생하면 예외 발생\n",
        "\n",
        "            data = response.json()\n",
        "            # API 응답에서 원하는 정보를 추출하여 문자열로 포맷팅합니다.\n",
        "            # 이 부분은 사용하는 API의 응답 구조에 따라 달라집니다.\n",
        "\n",
        "            # OpenWeatherMap 예시 응답 구조를 기반으로 데이터 추출\n",
        "            weather_description = data['weather'][0]['description']\n",
        "            temperature = data['main']['temp']\n",
        "            feels_like = data['main']['feels_like']\n",
        "            humidity = data['main']['humidity']\n",
        "\n",
        "            return (f\"현재 {city_name} 날씨 정보:\\n\"\n",
        "                    f\"✨ 날씨: {weather_description}\\n\"\n",
        "                    f\"🌡️ 온도: {temperature}°C (체감: {feels_like}°C)\\n\"\n",
        "                    f\"💧 습도: {humidity}%\\n\")\n",
        "\n",
        "        except httpx.RequestError as e:\n",
        "            logger.error(f\"API 요청 중 오류 발생: {e}\")\n",
        "            return \"날씨 정보를 가져오는 데 실패했습니다. 네트워크 연결을 확인하거나 API 키를 점검해주세요. 😞\"\n",
        "        except KeyError as e:\n",
        "            logger.error(f\"API 응답에서 키 오류 발생: {e}. 응답 구조가 예상과 다릅니다.\")\n",
        "            return \"날씨 정보를 처리하는 데 문제가 발생했습니다. (데이터 형식 오류) 🧐\"\n",
        "        except Exception as e:\n",
        "            logger.error(f\"예상치 못한 오류 발생: {e}\")\n",
        "            return \"날씨 정보를 가져오는 중 알 수 없는 오류가 발생했습니다. 🥺\"\n",
        "\n",
        "async def news_command(update: Update, context: ContextTypes.DEFAULT_TYPE):\n",
        "    ApiNewsKey=#뉴스apikey\n",
        "    if not context.args:\n",
        "        await update.message.reply_text(\"사용법: /news <검색어>\")\n",
        "        return\n",
        "\n",
        "    keyword = ' '.join(context.args)\n",
        "    url = f\"https://newsapi.org/v2/everything?q={keyword}&language=ko&apiKey={ApiNewsKey}\"\n",
        "\n",
        "    try:\n",
        "        response = requests.get(url)\n",
        "        data = response.json()\n",
        "\n",
        "        if 'articles' not in data:\n",
        "            await update.message.reply_text(\"뉴스를 가져오는 데 실패했습니다.\")\n",
        "            return\n",
        "\n",
        "        for i, article in enumerate(data['articles'][:5]):  # 상위 5개 뉴스만\n",
        "            title = article['title']\n",
        "            desc = article['description'] or \"설명 없음\"\n",
        "            await update.message.reply_text(f\"{i+1}. {title}\\n{desc}\\n\")\n",
        "    except Exception as e:\n",
        "        await update.message.reply_text(\"오류 발생: \" + str(e))\n",
        "\n",
        "# --- 기존 코드 (start 함수만 수정) ---\n",
        "async def start(update: Update, context: object) -> None:\n",
        "    \"\"\"/start 명령어를 받았을 때 응답합니다.\"\"\"\n",
        "    user = update.effective_user\n",
        "\n",
        "    # 1. 이미지 보내기 예시 (이전과 동일)\n",
        "    image_url = \"https://cdn.imweb.me/upload/S20210103c5204f5ed12ce/8017dcc999129.png\"\n",
        "    await context.bot.send_photo(\n",
        "        chat_id=update.effective_chat.id,\n",
        "        photo=image_url,\n",
        "        caption=\"저희 봇의 로고입니다!\",\n",
        "    )\n",
        "    logger.info(f\"Sent image to user {user.first_name}.\")\n",
        "\n",
        "    # --- 새로운 부분: API 호출하여 정보 가져오기 ---\n",
        "    api_info_result = await get_api_data()  # 위에서 정의한 API 호출 함수 실행\n",
        "\n",
        "    # 2. 소개 페이지 (HTML 형식의 꾸며진 텍스트와 링크)\n",
        "    introduction_text = f\"\"\"\n",
        "안녕하세요, <b>{user.mention_html()}</b>님! 👋\n",
        "저는 미래채움 <b>봇</b>입니다.\n",
        "\n",
        "{api_info_result} # API 호출 결과가 여기에 삽입됩니다!\n",
        "\n",
        "이 봇은 다음과 같은 기능을 제공해요:\n",
        "•  <code>/start</code>: 원주고 이미지와, 날씨 정보를 제공합니다\n",
        "• 에코기능이 있어서 따라 따라말하는 기능이 있습니다.\n",
        "•  <i>앞으로 더 많은 기능이 추가될 예정입니다 감사합니다</i>\n",
        "\n",
        "    \"\"\"\n",
        "\n",
        "    await update.message.reply_html(introduction_text)\n",
        "    logger.info(f\"User {user.first_name} started the bot and received intro with API data.\")\n",
        "\n",
        "\n",
        "# 나머지 echo, error_handler, main 함수는 이전과 동일합니다.\n",
        "async def echo(update: Update, context: object) -> None:\n",
        "    \"\"\"사용자의 메시지를 그대로 다시 보냅니다.\"\"\"\n",
        "    await update.message.reply_text(update.message.text)\n",
        "    logger.info(f\"Echoed message: {update.message.text}\")\n",
        "\n",
        "\n",
        "async def weather_command(update: Update, context: object) -> None:\n",
        "    \"\"\"/weather 명령어를 받았을 때 날씨 정보를 응답합니다.\"\"\"\n",
        "    user = update.effective_user\n",
        "    logger.info(f\"User {user.first_name} requested weather info.\")\n",
        "\n",
        "    # get_api_data() 함수를 호출하여 날씨 정보를 가져옵니다.\n",
        "    weather_info = await get_api_data()\n",
        "\n",
        "    # 가져온 날씨 정보를 사용자에게 메시지로 보냅니다.\n",
        "    await update.message.reply_text(weather_info)\n",
        "\n",
        "\n",
        "async def error_handler(update: Update, context: object) -> None:\n",
        "    \"\"\"봇의 오류를 로깅합니다.\"\"\"\n",
        "    logger.warning(f\"업데이트 {update}에서 오류가 발생했습니다: {context.error}\")\n",
        "\n",
        "\n",
        "async def main() -> None:\n",
        "    \"\"\"봇을 실행합니다.\"\"\"\n",
        "    application = Application.builder().token(TOKEN).build()\n",
        "\n",
        "    application.add_handler(CommandHandler(\"start\", start))\n",
        "    application.add_handler(CommandHandler(\"weather\", weather_command))  # <-- 이 줄 추가!\n",
        "    application.add_handler(CommandHandler(\"news\", news_command))\n",
        "    application.add_handler(MessageHandler(filters.TEXT & ~filters.COMMAND, echo))\n",
        "    application.add_error_handler(error_handler)\n",
        "\n",
        "    logger.info(\"봇을 시작합니다...\")\n",
        "    application.run_polling()\n",
        "    logger.info(\"봇이 종료되었습니다.\")\n",
        "\n",
        "\n",
        "\n",
        "if __name__ == \"__main__\":\n",
        "    try:\n",
        "        asyncio.run(main())\n",
        "    except RuntimeError as e:\n",
        "        if \"cannot close a running event loop\" in str(e).lower() or \"cannot be called from a running event loop\" in str(e).lower():\n",
        "            nest_asyncio.apply()\n",
        "            loop = asyncio.get_event_loop()\n",
        "            loop.run_until_complete(main())  \n",
        "        else:\n",
        "            raise"
      ]
    }
  ],
  "metadata": {
    "colab": {
      "provenance": []
    },
    "kernelspec": {
      "display_name": "Python 3",
      "name": "python3"
    },
    "language_info": {
      "name": "python"
    }
  },
  "nbformat": 4,
  "nbformat_minor": 0
}
